.command.run: line 284: TZ: unbound variable
2025-08-19 22:26:02  INFO:Starting script
2025-08-19 22:26:02  INFO:Using event: ECI_UC7_Seg
2025-08-19 22:26:02  INFO:Assessment data: ['assessment_results.json']
2025-08-19 22:26:02  ERROR:'hausdorff95'
Traceback (most recent call last):
  File "/app/aggregation.py", line 333, in add_to_aggregation
    participant["metric_y"] = challenge[plot["y_axis"]
KeyError: 'hausdorff95'
2025-08-19 22:26:02  ERROR:'hausdorff95'
Traceback (most recent call last):
  File "/app/aggregation.py", line 333, in add_to_aggregation
    participant["metric_y"] = challenge[plot["y_axis"]
KeyError: 'hausdorff95'
2025-08-19 22:26:02  ERROR:'assd'
Traceback (most recent call last):
  File "/app/aggregation.py", line 333, in add_to_aggregation
    participant["metric_y"] = challenge[plot["y_axis"]
KeyError: 'assd'
2025-08-19 22:26:02  WARNING:No handles with labels found to put in legend.
2025-08-19 22:26:02  WARNING:No handles with labels found to put in legend.
2025-08-19 22:26:02  WARNING:No handles with labels found to put in legend.
2025-08-19 22:26:03  WARNING:No handles with labels found to put in legend.
2025-08-19 22:26:03  WARNING:No handles with labels found to put in legend.
2025-08-19 22:26:03  WARNING:No handles with labels found to put in legend.
2025-08-19 22:26:03  WARNING:No handles with labels found to put in legend.
2025-08-19 22:26:03  WARNING:No handles with labels found to put in legend.
2025-08-19 22:26:03  WARNING:No handles with labels found to put in legend.
2025-08-19 22:26:03  WARNING:No handles with labels found to put in legend.
2025-08-19 22:26:03  WARNING:No handles with labels found to put in legend.
2025-08-19 22:26:03  WARNING:No handles with labels found to put in legend.
2025-08-19 22:26:03  ERROR:list index out of range
Traceback (most recent call last):
  File "/app/aggregation.py", line 366, in <module>
    main(options)
  File "/app/aggregation.py", line 169, in main
    challenge_dir, aggr_object, challenge_id, "RAW")
  File "/app/assessment_chart/assessment_chart.py", line 335, in print_chart
    p_frontX, p_frontY = pareto_frontier(x_values, y_values, maxX=max_x, maxY=max_y)
  File "/app/assessment_chart/assessment_chart.py", line 23, in pareto_frontier
    p_front = [myList[0]]
IndexError: list index out of range
Traceback (most recent call last):
  File "/app/aggregation.py", line 371, in <module>
    raise e
  File "/app/aggregation.py", line 366, in <module>
    main(options)
  File "/app/aggregation.py", line 169, in main
    challenge_dir, aggr_object, challenge_id, "RAW")
  File "/app/assessment_chart/assessment_chart.py", line 335, in print_chart
    p_frontX, p_frontY = pareto_frontier(x_values, y_values, maxX=max_x, maxY=max_y)
  File "/app/assessment_chart/assessment_chart.py", line 23, in pareto_frontier
    p_front = [myList[0]]
IndexError: list index out of range
